{"uuid": "5d7b408a-61da-4ce8-bcdb-73163e6d70e9", "children": ["df9f4c48-d906-4bba-88d7-5c4b09018f43"], "befores": [{"name": "_Class__pytest_setup_class", "status": "passed", "start": 1647339031004, "stop": 1647339032954}], "afters": [{"name": "_Class__pytest_setup_class::0", "status": "broken", "statusDetails": {"message": "urllib3.exceptions.MaxRetryError: HTTPConnectionPool(host='localhost', port=49986): Max retries exceeded with url: /session/002742c61470615e095aa427778a5303/window (Caused by NewConnectionError('<urllib3.connection.HTTPConnection object at 0x7fea66035940>: Failed to establish a new connection: [Errno 61] Connection refused'))\n", "trace": "  File \"/Library/Frameworks/Python.framework/Versions/3.9/lib/python3.9/site-packages/allure_commons/_allure.py\", line 200, in __call__\n    return self._fixture_function(*args, **kwargs)\n  File \"/Users/yangzhiqi/PycharmProjects/Selenium/venv/lib/python3.9/site-packages/_pytest/fixtures.py\", line 800, in _teardown_yield_fixture\n    next(it)\n  File \"/Users/yangzhiqi/PycharmProjects/Selenium/venv/lib/python3.9/site-packages/_pytest/python.py\", line 705, in xunit_setup_class_fixture\n    _call_with_optional_argument(func, self.obj)\n  File \"/Users/yangzhiqi/PycharmProjects/Selenium/venv/lib/python3.9/site-packages/_pytest/python.py\", line 632, in _call_with_optional_argument\n    func(arg)\n  File \"/Users/yangzhiqi/PycharmProjects/Selenium/TestCase/test_vue.py\", line 45, in teardown_class\n    self.driver.close()\n  File \"/Users/yangzhiqi/PycharmProjects/Selenium/venv/lib/python3.9/site-packages/selenium/webdriver/remote/webdriver.py\", line 938, in close\n    self.execute(Command.CLOSE)\n  File \"/Users/yangzhiqi/PycharmProjects/Selenium/venv/lib/python3.9/site-packages/selenium/webdriver/remote/webdriver.py\", line 423, in execute\n    response = self.command_executor.execute(driver_command, params)\n  File \"/Users/yangzhiqi/PycharmProjects/Selenium/venv/lib/python3.9/site-packages/selenium/webdriver/remote/remote_connection.py\", line 316, in execute\n    return self._request(command_info[0], url, body=data)\n  File \"/Users/yangzhiqi/PycharmProjects/Selenium/venv/lib/python3.9/site-packages/selenium/webdriver/remote/remote_connection.py\", line 338, in _request\n    resp = self._conn.request(method, url, body=body, headers=headers)\n  File \"/Library/Frameworks/Python.framework/Versions/3.9/lib/python3.9/site-packages/urllib3/request.py\", line 74, in request\n    return self.request_encode_url(\n  File \"/Library/Frameworks/Python.framework/Versions/3.9/lib/python3.9/site-packages/urllib3/request.py\", line 96, in request_encode_url\n    return self.urlopen(method, url, **extra_kw)\n  File \"/Library/Frameworks/Python.framework/Versions/3.9/lib/python3.9/site-packages/urllib3/poolmanager.py\", line 375, in urlopen\n    response = conn.urlopen(method, u.request_uri, **kw)\n  File \"/Library/Frameworks/Python.framework/Versions/3.9/lib/python3.9/site-packages/urllib3/connectionpool.py\", line 813, in urlopen\n    return self.urlopen(\n  File \"/Library/Frameworks/Python.framework/Versions/3.9/lib/python3.9/site-packages/urllib3/connectionpool.py\", line 813, in urlopen\n    return self.urlopen(\n  File \"/Library/Frameworks/Python.framework/Versions/3.9/lib/python3.9/site-packages/urllib3/connectionpool.py\", line 813, in urlopen\n    return self.urlopen(\n  File \"/Library/Frameworks/Python.framework/Versions/3.9/lib/python3.9/site-packages/urllib3/connectionpool.py\", line 785, in urlopen\n    retries = retries.increment(\n  File \"/Library/Frameworks/Python.framework/Versions/3.9/lib/python3.9/site-packages/urllib3/util/retry.py\", line 592, in increment\n    raise MaxRetryError(_pool, url, error or ResponseError(cause))\n"}, "start": 1647339099985, "stop": 1647339101997}], "start": 1647339031004, "stop": 1647339101997}